<?xml version="1.0" encoding="utf-8"?>
<!-- This URDF was automatically created by SolidWorks to URDF Exporter! Originally created by Stephen Brawner (brawner@gmail.com) 
     Commit Version: 1.6.0-4-g7f85cfe  Build Version: 1.6.7995.38578
     For more information, please see http://wiki.ros.org/sw_urdf_exporter -->
<robot
  name="s200_4wd_robot_dual_antenna">
  <link
    name="base_link">
    <inertial>
      <origin
        xyz="-0.016206 -0.0010825 0.092969"
        rpy="0 0 0" />
      <mass
        value="14.207" />
      <inertia
        ixx="0.10104"
        ixy="-2.6991E-06"
        ixz="0.003759"
        iyy="0.11424"
        iyz="-3.6837E-07"
        izz="0.1932" />
    </inertial>
    <visual>
      <origin
        xyz="0 0 0"
        rpy="0 0 0" />
      <geometry>
        <mesh
          filename="package://wheeltec_robot_urdf/meshes/autoware_s200_dual_antenna_meshes/base_link.STL" />
      </geometry>
      <material
        name="">
        <color
          rgba="0.74118 0.90196 0.95686 1" />
      </material>
    </visual>
    <collision>
      <origin
        xyz="0 0 0"
        rpy="0 0 0" />
      <geometry>
        <mesh
          filename="package://wheeltec_robot_urdf/meshes/autoware_s200_dual_antenna_meshes/base_link.STL" />
      </geometry>
    </collision>
  </link>
  <link
    name="lf_wheel_link">
    <inertial>
      <origin
        xyz="2.0303E-06 -0.0025543 1.1196E-06"
        rpy="0 0 0" />
      <mass
        value="4.2268" />
      <inertia
        ixx="0.012875"
        ixy="2.3428E-07"
        ixz="-2.212E-07"
        iyy="0.023457"
        iyz="1.1261E-07"
        izz="0.012874" />
    </inertial>
    <visual>
      <origin
        xyz="0 0 0"
        rpy="0 0 0" />
      <geometry>
        <mesh
          filename="package://wheeltec_robot_urdf/meshes/autoware_s200_dual_antenna_meshes/lf_wheel_link.STL" />
      </geometry>
      <material
        name="">
        <color
          rgba="0.37647 0.37647 0.37647 1" />
      </material>
    </visual>
    <collision>
      <origin
        xyz="0 0 0"
        rpy="0 0 0" />
      <geometry>
        <mesh
          filename="package://wheeltec_robot_urdf/meshes/autoware_s200_dual_antenna_meshes/lf_wheel_link.STL" />
      </geometry>
    </collision>
  </link>
  <joint
    name="lf_wheel_joint"
    type="continuous">
    <origin
      xyz="0.176 0.2942 0.037"
      rpy="0 0 0" />
    <parent
      link="base_link" />
    <child
      link="lf_wheel_link" />
    <axis
      xyz="0 -1 0" />
  </joint>
  <link
    name="lb_wheel_link">
    <inertial>
      <origin
        xyz="2.03032748341547E-06 -0.00255430643367516 1.11959237331094E-06"
        rpy="0 0 0" />
      <mass
        value="4.22677692250261" />
      <inertia
        ixx="0.0128745482757213"
        ixy="2.34279426632852E-07"
        ixz="-2.21205388116043E-07"
        iyy="0.0234566776842193"
        iyz="1.12612879260104E-07"
        izz="0.012874235039733" />
    </inertial>
    <visual>
      <origin
        xyz="0 0 0"
        rpy="0 0 0" />
      <geometry>
        <mesh
          filename="package://wheeltec_robot_urdf/meshes/autoware_s200_dual_antenna_meshes/lb_wheel_link.STL" />
      </geometry>
      <material
        name="">
        <color
          rgba="0.376470588235294 0.376470588235294 0.376470588235294 1" />
      </material>
    </visual>
    <collision>
      <origin
        xyz="0 0 0"
        rpy="0 0 0" />
      <geometry>
        <mesh
          filename="package://wheeltec_robot_urdf/meshes/autoware_s200_dual_antenna_meshes/lb_wheel_link.STL" />
      </geometry>
    </collision>
  </link>
  <joint
    name="lb_wheel_joint"
    type="continuous">
    <origin
      xyz="-0.176 0.2942 0.037"
      rpy="0 0 0" />
    <parent
      link="base_link" />
    <child
      link="lb_wheel_link" />
    <axis
      xyz="0 1 0" />
  </joint>
  <link
    name="rb_wheel_link">
    <inertial>
      <origin
        xyz="-2.03029462447768E-06 0.00255430644377075 1.11960752291473E-06"
        rpy="0 0 0" />
      <mass
        value="4.22677692233724" />
      <inertia
        ixx="0.012874548274951"
        ixy="2.34281779981103E-07"
        ixz="2.21205446250114E-07"
        iyy="0.0234566776732399"
        iyz="-1.12608917585945E-07"
        izz="0.0128742350373087" />
    </inertial>
    <visual>
      <origin
        xyz="0 0 0"
        rpy="0 0 0" />
      <geometry>
        <mesh
          filename="package://wheeltec_robot_urdf/meshes/autoware_s200_dual_antenna_meshes/rb_wheel_link.STL" />
      </geometry>
      <material
        name="">
        <color
          rgba="0.376470588235294 0.376470588235294 0.376470588235294 1" />
      </material>
    </visual>
    <collision>
      <origin
        xyz="0 0 0"
        rpy="0 0 0" />
      <geometry>
        <mesh
          filename="package://wheeltec_robot_urdf/meshes/autoware_s200_dual_antenna_meshes/rb_wheel_link.STL" />
      </geometry>
    </collision>
  </link>
  <joint
    name="rb_wheel_joint"
    type="continuous">
    <origin
      xyz="-0.176 -0.2942 0.037"
      rpy="0 0 0" />
    <parent
      link="base_link" />
    <child
      link="rb_wheel_link" />
    <axis
      xyz="0 1 0" />
  </joint>
  <link
    name="rf_wheel_link">
    <inertial>
      <origin
        xyz="-2.03030820233874E-06 0.00255430644214427 1.11959548654283E-06"
        rpy="0 0 0" />
      <mass
        value="4.22677692186316" />
      <inertia
        ixx="0.0128745482759271"
        ixy="2.34281359536838E-07"
        ixz="2.21208355836275E-07"
        iyy="0.0234566776743326"
        iyz="-1.12610349776139E-07"
        izz="0.0128742350344692" />
    </inertial>
    <visual>
      <origin
        xyz="0 0 0"
        rpy="0 0 0" />
      <geometry>
        <mesh
          filename="package://wheeltec_robot_urdf/meshes/autoware_s200_dual_antenna_meshes/rf_wheel_link.STL" />
      </geometry>
      <material
        name="">
        <color
          rgba="1 1 1 1" />
      </material>
    </visual>
    <collision>
      <origin
        xyz="0 0 0"
        rpy="0 0 0" />
      <geometry>
        <mesh
          filename="package://wheeltec_robot_urdf/meshes/autoware_s200_dual_antenna_meshes/rf_wheel_link.STL" />
      </geometry>
    </collision>
  </link>
  <joint
    name="rf_wheel_joint"
    type="continuous">
    <origin
      xyz="0.176 -0.2942 0.037"
      rpy="0 0 0" />
    <parent
      link="base_link" />
    <child
      link="rf_wheel_link" />
    <axis
      xyz="0 -1 0" />
  </joint>
  <link
    name="laser_link">
    <inertial>
      <origin
        xyz="-0.00426716639563593 6.84539252775691E-05 -0.0217512821660334"
        rpy="0 0 0" />
      <mass
        value="0.208180628354358" />
      <inertia
        ixx="0.000181169417419153"
        ixy="2.42714579673972E-07"
        ixz="-2.21590809978481E-06"
        iyy="0.000183115154714868"
        iyz="-1.46637875426403E-10"
        izz="0.000283237424426077" />
    </inertial>
    <visual>
      <origin
        xyz="0 0 0"
        rpy="0 0 0" />
      <geometry>
        <mesh
          filename="package://wheeltec_robot_urdf/meshes/autoware_s200_dual_antenna_meshes/laser_link.STL" />
      </geometry>
      <material
        name="">
        <color
          rgba="1 1 1 1" />
      </material>
    </visual>
    <collision>
      <origin
        xyz="0 0 0"
        rpy="0 0 0" />
      <geometry>
        <mesh
          filename="package://wheeltec_robot_urdf/meshes/autoware_s200_dual_antenna_meshes/laser_link.STL" />
      </geometry>
    </collision>
  </link>
  <joint
    name="laser_joint"
    type="fixed">
    <origin
      xyz="0.13497 0 0.27685"
      rpy="0 0 0" />
    <parent
      link="base_link" />
    <child
      link="laser_link" />
    <axis
      xyz="0 0 0" />
  </joint>
  <link
    name="camera_link">
    <inertial>
      <origin
        xyz="-4.27512826806087E-08 -3.48614412950819E-07 1.07624261950351E-07"
        rpy="0 0 0" />
      <mass
        value="0.0559842512077871" />
      <inertia
        ixx="0.000130810959338969"
        ixy="1.20255128279194E-07"
        ixz="1.62335437078887E-06"
        iyy="1.91148634967707E-05"
        iyz="-2.80016756404559E-08"
        izz="0.000131387469522791" />
    </inertial>
    <visual>
      <origin
        xyz="0 0 0"
        rpy="0 0 0" />
      <geometry>
        <mesh
          filename="package://wheeltec_robot_urdf/meshes/autoware_s200_dual_antenna_meshes/camera_link.STL" />
      </geometry>
      <material
        name="">
        <color
          rgba="1 1 1 1" />
      </material>
    </visual>
    <collision>
      <origin
        xyz="0 0 0"
        rpy="0 0 0" />
      <geometry>
        <mesh
          filename="package://wheeltec_robot_urdf/meshes/autoware_s200_dual_antenna_meshes/camera_link.STL" />
      </geometry>
    </collision>
  </link>
  <joint
    name="camera_joint"
    type="fixed">
    <origin
      xyz="0.26369 7.6608E-05 0.1609"
      rpy="0 0 0" />
    <parent
      link="base_link" />
    <child
      link="camera_link" />
    <axis
      xyz="0 0 0" />
  </joint>
  <link
    name="controller_link">
    <inertial>
      <origin
        xyz="-0.00127624217022466 -0.0334480323847527 -0.0673279568183753"
        rpy="0 0 0" />
      <mass
        value="35.4980987325577" />
      <inertia
        ixx="2.51320480824053"
        ixy="0.00157755837672266"
        ixz="0.162118929982393"
        iyy="1.5404213360186"
        iyz="0.000933314662272007"
        izz="3.01103428608651" />
    </inertial>
    <visual>
      <origin
        xyz="0 0 0"
        rpy="0 0 0" />
      <geometry>
        <mesh
          filename="package://wheeltec_robot_urdf/meshes/autoware_s200_dual_antenna_meshes/controller_link.STL" />
      </geometry>
      <material
        name="">
        <color
          rgba="0.741176470588235 0.901960784313726 0.956862745098039 1" />
      </material>
    </visual>
    <collision>
      <origin
        xyz="0 0 0"
        rpy="0 0 0" />
      <geometry>
        <mesh
          filename="package://wheeltec_robot_urdf/meshes/autoware_s200_dual_antenna_meshes/controller_link.STL" />
      </geometry>
    </collision>
  </link>
  <joint
    name="controller_joint"
    type="fixed">
    <origin
      xyz="-0.015598 0.033015 0.16714"
      rpy="0 0 0" />
    <parent
      link="base_link" />
    <child
      link="controller_link" />
    <axis
      xyz="0 0 0" />
  </joint>
  <link
    name="mushroom_link">
    <inertial>
      <origin
        xyz="-0.043616185508487 3.87291246908248E-06 -0.111336311329767"
        rpy="0 0 0" />
      <mass
        value="2.76431890819086" />
      <inertia
        ixx="0.00586275774606513"
        ixy="2.03993427694772E-09"
        ixz="9.97673703738476E-19"
        iyy="0.00585800987170118"
        iyz="-4.2837844274439E-17"
        izz="0.0101855408811855" />
    </inertial>
    <visual>
      <origin
        xyz="0 0 0"
        rpy="0 0 0" />
      <geometry>
        <mesh
          filename="package://wheeltec_robot_urdf/meshes/autoware_s200_dual_antenna_meshes/mushroom_link.STL" />
      </geometry>
      <material
        name="">
        <color
          rgba="0.741176470588235 0.901960784313726 0.956862745098039 1" />
      </material>
    </visual>
    <collision>
      <origin
        xyz="0 0 0"
        rpy="0 0 0" />
      <geometry>
        <mesh
          filename="package://wheeltec_robot_urdf/meshes/autoware_s200_dual_antenna_meshes/mushroom_link.STL" />
      </geometry>
    </collision>
  </link>
  <joint
    name="mushroom_joint"
    type="fixed">
    <origin
      xyz="-0.07094 0 0.45681"
      rpy="0 0 0" />
    <parent
      link="base_link" />
    <child
      link="mushroom_link" />
    <axis
      xyz="0 0 0" />
  </joint>
</robot>